<?xml version="1.0" encoding="UTF-8"?>
<robot>
    <joint name="Joint1" type="revolute">
        <axis xyz="0 0 1" />
        <limit effort="10" lower="-3" upper="3" velocity="0.0" />
        <parent link="Base" />
        <child link="Link1" />
        <origin xyz="0 0 0.064273" rpy=" 0 0 0" />
    </joint>

    <joint name="Joint2" type="revolute">
        <axis xyz="-1 0 0" />
        <limit effort="10" lower="-3" upper="3" velocity="0.0" />
        <parent link="Link1" />
        <child link="Link2" />
        <origin xyz="-0.0041395 -0.0081353 0.021592" rpy="0 0 0" />
    </joint>

    <joint name="Joint3" type="revolute">
        <axis xyz="1 0 0" />
        <parent link="Link2" />
        <child link="Link3" />
        <limit effort="10" lower="-1.45" upper="1.45" velocity="0.0" />
        <origin xyz="-0.0033882 0 0.12845" rpy="-0.0011788 0 0" />
    </joint>

    <joint name="Joint4" type="revolute">
        <axis xyz="1 0 0" />
        <limit effort="10" lower="-3" upper="3" velocity="0.0" />
        <parent link="Link2" />
        <child link="Link4" />
        <origin xyz="0.032307 5.2901E-05 0.12853" rpy="0 0 0" />
    </joint>

    <joint name="Joint5" type="revolute">
        <axis xyz="-1 0 0" />
        <limit effort="10" lower="-3" upper="3" velocity="0.0" />
        <parent link="Link1" />
        <child link="Link5" />
        <origin xyz="0.018067 0.026256 0.045902" rpy="0 0 0" />
    </joint>

    <joint name="Joint6" type="revolute">
        <axis xyz="-1 0 0" />
        <limit effort="10" lower="-3" upper="3" velocity="0.0" />
        <parent link="Link1" />
        <child link="Link6" />
        <origin xyz="-0.0060277 -0.0081353 0.021592" rpy="0 0 0" />
    </joint>

    <joint name="Joint7" type="revolute">
        <axis xyz="-1 0 0" />
        <limit effort="10" lower="-3" upper="3" velocity="0.0" />
        <parent link="Link6" />
        <child link="Link7" />
        <origin xyz="0 0.0432 0" rpy="0 0 0" />
    </joint>

    <joint name="Joint8" type="revolute">
        <axis xyz="1 0 0" />
        <limit effort="10" lower="-3" upper="3" velocity="0.0" />
        <parent link="Link3" />
        <child link="Link8" />
        <origin xyz="0 -0.138 -0.00016405" rpy="0.0011788 0 0" />
    </joint>

    <joint name="Joint9" type="revolute">
        <axis xyz="-1 0 0" />
        <limit effort="10" lower="-3" upper="3" velocity="0.0" />
        <parent link="Link8" />
        <child link="Link9" />
        <origin xyz="0.031695 -0.034122 0.024493" rpy="0 0 0" />
    </joint>

    <!-- virtual joints needed for vacuum_gripper plugin -->
    <joint name="virtual_end_joint" type="revolute">
        <axis xyz="0 0 1" />
        <parent link="Link8" />
        <child link="virtual_end_effector" />
        <origin xyz="0.01 -0.017 -0.075" rpy=" 0 0 0" />
        <limit effort="1" lower="0" upper="0" velocity="0.0" />
    </joint>

</robot>